<sdf version='1.6'>
  <world name='default'>
    <light name='sun' type='directional'>
      <cast_shadows>1</cast_shadows>
      <pose frame=''>0 0 10 0 -0 0</pose>
      <diffuse>0.8 0.8 0.8 1</diffuse>
      <specular>0.2 0.2 0.2 1</specular>
      <attenuation>
        <range>1000</range>
        <constant>0.9</constant>
        <linear>0.01</linear>
        <quadratic>0.001</quadratic>
      </attenuation>
      <direction>-0.5 0.1 -0.9</direction>
    </light>
    <model name='ground_plane'>
      <static>1</static>
      <link name='link'>
        <collision name='collision'>
          <geometry>
            <plane>
              <normal>0 0 1</normal>
              <size>100 100</size>
            </plane>
          </geometry>
          <surface>
            <contact>
              <collide_bitmask>65535</collide_bitmask>
              <ode/>
            </contact>
            <friction>
              <ode>
                <mu>100</mu>
                <mu2>50</mu2>
              </ode>
              <torsional>
                <ode/>
              </torsional>
            </friction>
            <bounce/>
          </surface>
          <max_contacts>10</max_contacts>
        </collision>
        <visual name='visual'>
          <cast_shadows>0</cast_shadows>
          <geometry>
            <plane>
              <normal>0 0 1</normal>
              <size>100 100</size>
            </plane>
          </geometry>
          <material>
            <script>
              <uri>file://media/materials/scripts/gazebo.material</uri>
              <name>Gazebo/Grey</name>
            </script>
          </material>
        </visual>
        <self_collide>0</self_collide>
        <enable_wind>0</enable_wind>
        <kinematic>0</kinematic>
      </link>
    </model>
    <gravity>0 0 -9.8</gravity>
    <magnetic_field>6e-06 2.3e-05 -4.2e-05</magnetic_field>
    <atmosphere type='adiabatic'/>
    <physics name='default_physics' default='0' type='ode'>
      <max_step_size>0.001</max_step_size>
      <real_time_factor>1</real_time_factor>
      <real_time_update_rate>1000</real_time_update_rate>
    </physics>
    <scene>
      <ambient>0.4 0.4 0.4 1</ambient>
      <background>0.7 0.7 0.7 1</background>
      <shadows>1</shadows>
    </scene>
    <audio>
      <device>default</device>
    </audio>
    <wind/>
    <spherical_coordinates>
      <surface_model>EARTH_WGS84</surface_model>
      <latitude_deg>0</latitude_deg>
      <longitude_deg>0</longitude_deg>
      <elevation>0</elevation>
      <heading_deg>0</heading_deg>
    </spherical_coordinates>
    <model name='quadruped'>
      <link name='dummy'>
        <pose frame=''>0 0 0 0 -0 0</pose>
        <inertial>
          <pose frame=''>0 0 0 0 -0 0</pose>
          <mass>1</mass>
          <inertia>
            <ixx>1</ixx>
            <ixy>0</ixy>
            <ixz>0</ixz>
            <iyy>1</iyy>
            <iyz>0</iyz>
            <izz>1</izz>
          </inertia>
        </inertial>
        <collision name='dummy_fixed_joint_lump__body_collision'>
          <pose frame=''>0 0 0 1.57 -0 1.57</pose>
          <geometry>
            <mesh>
              <scale>1 1 1</scale>
              <uri>/home/francisco/quadruped_ws/src/quadruped_robot/quadruped_description/meshes/frame_aluminum_motor_case.stl</uri>
            </mesh>
          </geometry>
          <max_contacts>10</max_contacts>
          <surface>
            <contact>
              <ode/>
            </contact>
            <bounce/>
            <friction>
              <torsional>
                <ode/>
              </torsional>
              <ode/>
            </friction>
          </surface>
        </collision>
        <visual name='dummy_fixed_joint_lump__body_visual'>
          <pose frame=''>0 0 0 1.57 -0 1.57</pose>
          <geometry>
            <mesh>
              <scale>1 1 1</scale>
              <uri>/home/francisco/quadruped_ws/src/quadruped_robot/quadruped_description/meshes/frame_aluminum_motor_case.stl</uri>
            </mesh>
          </geometry>
        </visual>
        <self_collide>0</self_collide>
        <enable_wind>0</enable_wind>
        <kinematic>0</kinematic>
      </link>
      <link name='back_left_u'>
        <pose frame=''>-0.11 0.05 0 0 -0 3.14</pose>
        <inertial>
          <pose frame=''>0 0 0 0 -0 0</pose>
          <mass>1</mass>
          <inertia>
            <ixx>1</ixx>
            <ixy>0</ixy>
            <ixz>0</ixz>
            <iyy>1</iyy>
            <iyz>0</iyz>
            <izz>1</izz>
          </inertia>
        </inertial>
        <collision name='back_left_u_collision'>
          <pose frame=''>0 0 0 -1.57159 0.001593 -1.57159</pose>
          <geometry>
            <mesh>
              <scale>1 1 1</scale>
              <uri>/home/francisco/quadruped_ws/src/quadruped_robot/quadruped_description/meshes/joint_gear_upper_assembly.stl</uri>
            </mesh>
          </geometry>
          <max_contacts>10</max_contacts>
          <surface>
            <contact>
              <ode/>
            </contact>
            <bounce/>
            <friction>
              <torsional>
                <ode/>
              </torsional>
              <ode/>
            </friction>
          </surface>
        </collision>
        <visual name='back_left_u_visual'>
          <pose frame=''>0 0 0 -1.57159 0.001593 -1.57159</pose>
          <geometry>
            <mesh>
              <scale>1 1 1</scale>
              <uri>/home/francisco/quadruped_ws/src/quadruped_robot/quadruped_description/meshes/joint_gear_upper_assembly.stl</uri>
            </mesh>
          </geometry>
        </visual>
        <self_collide>0</self_collide>
        <enable_wind>0</enable_wind>
        <kinematic>0</kinematic>
      </link>
      <joint name='back_left_joint1' type='revolute'>
        <child>back_left_u</child>
        <parent>dummy</parent>
        <axis>
          <xyz>-0.001593 -0.999999 0</xyz>
          <limit>
            <lower>-3.14</lower>
            <upper>3.14</upper>
            <effort>1000</effort>
            <velocity>0.5</velocity>
          </limit>
          <dynamics>
            <spring_reference>0</spring_reference>
            <spring_stiffness>0</spring_stiffness>
          </dynamics>
          <use_parent_model_frame>1</use_parent_model_frame>
        </axis>
      </joint>
      <link name='back_left_d'>
        <pose frame=''>-0.509992 0.055637 0 0 -0 3.14</pose>
        <inertial>
          <pose frame=''>0 0 0 0 -0 0</pose>
          <mass>1</mass>
          <inertia>
            <ixx>1</ixx>
            <ixy>0</ixy>
            <ixz>0</ixz>
            <iyy>1</iyy>
            <iyz>0</iyz>
            <izz>1</izz>
          </inertia>
        </inertial>
        <collision name='back_left_d_collision'>
          <pose frame=''>0 0 0 -1.57 -0 -1.57</pose>
          <geometry>
            <mesh>
              <scale>1 1 1</scale>
              <uri>/home/francisco/quadruped_ws/src/quadruped_robot/quadruped_description/meshes/Assembly_lower_link_v2.stl</uri>
            </mesh>
          </geometry>
          <max_contacts>10</max_contacts>
          <surface>
            <contact>
              <ode/>
            </contact>
            <bounce/>
            <friction>
              <torsional>
                <ode/>
              </torsional>
              <ode/>
            </friction>
          </surface>
        </collision>
        <visual name='back_left_d_visual'>
          <pose frame=''>0 0 0 -1.57 -0 -1.57</pose>
          <geometry>
            <mesh>
              <scale>1 1 1</scale>
              <uri>/home/francisco/quadruped_ws/src/quadruped_robot/quadruped_description/meshes/Assembly_lower_link_v2.stl</uri>
            </mesh>
          </geometry>
        </visual>
        <self_collide>0</self_collide>
        <enable_wind>0</enable_wind>
        <kinematic>0</kinematic>
      </link>
      <joint name='back_left_joint2' type='revolute'>
        <child>back_left_d</child>
        <parent>back_left_u</parent>
        <axis>
          <xyz>-0.001593 -0.999999 0</xyz>
          <limit>
            <lower>-3.14</lower>
            <upper>3.14</upper>
            <effort>1000</effort>
            <velocity>0.5</velocity>
          </limit>
          <dynamics>
            <spring_reference>0</spring_reference>
            <spring_stiffness>0</spring_stiffness>
          </dynamics>
          <use_parent_model_frame>1</use_parent_model_frame>
        </axis>
      </joint>
      <link name='back_right_u'>
        <pose frame=''>-0.11 -0.05 0 0 -0 3.14</pose>
        <inertial>
          <pose frame=''>0 0 0 0 -0 0</pose>
          <mass>1</mass>
          <inertia>
            <ixx>1</ixx>
            <ixy>0</ixy>
            <ixz>0</ixz>
            <iyy>1</iyy>
            <iyz>0</iyz>
            <izz>1</izz>
          </inertia>
        </inertial>
        <collision name='back_right_u_collision'>
          <pose frame=''>0 0 0 1.57 -0 1.57</pose>
          <geometry>
            <mesh>
              <scale>1 1 1</scale>
              <uri>/home/francisco/quadruped_ws/src/quadruped_robot/quadruped_description/meshes/joint_gear_upper_assembly.stl</uri>
            </mesh>
          </geometry>
          <max_contacts>10</max_contacts>
          <surface>
            <contact>
              <ode/>
            </contact>
            <bounce/>
            <friction>
              <torsional>
                <ode/>
              </torsional>
              <ode/>
            </friction>
          </surface>
        </collision>
        <visual name='back_right_u_visual'>
          <pose frame=''>0 0 0 1.57 -0 1.57</pose>
          <geometry>
            <mesh>
              <scale>1 1 1</scale>
              <uri>/home/francisco/quadruped_ws/src/quadruped_robot/quadruped_description/meshes/joint_gear_upper_assembly.stl</uri>
            </mesh>
          </geometry>
        </visual>
        <self_collide>0</self_collide>
        <enable_wind>0</enable_wind>
        <kinematic>0</kinematic>
      </link>
      <joint name='back_right_joint1' type='revolute'>
        <child>back_right_u</child>
        <parent>dummy</parent>
        <axis>
          <xyz>-0.001593 -0.999999 0</xyz>
          <limit>
            <lower>-3.14</lower>
            <upper>3.14</upper>
            <effort>1000</effort>
            <velocity>0.5</velocity>
          </limit>
          <dynamics>
            <spring_reference>0</spring_reference>
            <spring_stiffness>0</spring_stiffness>
          </dynamics>
          <use_parent_model_frame>1</use_parent_model_frame>
        </axis>
      </joint>
      <link name='back_right_d'>
        <pose frame=''>-0.510007 -0.054363 0 0 -0 3.14</pose>
        <inertial>
          <pose frame=''>0 0 0 0 -0 0</pose>
          <mass>1</mass>
          <inertia>
            <ixx>1</ixx>
            <ixy>0</ixy>
            <ixz>0</ixz>
            <iyy>1</iyy>
            <iyz>0</iyz>
            <izz>1</izz>
          </inertia>
        </inertial>
        <collision name='back_right_d_collision'>
          <pose frame=''>0 0 0 1.57 -0 1.57</pose>
          <geometry>
            <mesh>
              <scale>1 1 1</scale>
              <uri>/home/francisco/quadruped_ws/src/quadruped_robot/quadruped_description/meshes/Assembly_lower_link_v2.stl</uri>
            </mesh>
          </geometry>
          <max_contacts>10</max_contacts>
          <surface>
            <contact>
              <ode/>
            </contact>
            <bounce/>
            <friction>
              <torsional>
                <ode/>
              </torsional>
              <ode/>
            </friction>
          </surface>
        </collision>
        <visual name='back_right_d_visual'>
          <pose frame=''>0 0 0 1.57 -0 1.57</pose>
          <geometry>
            <mesh>
              <scale>1 1 1</scale>
              <uri>/home/francisco/quadruped_ws/src/quadruped_robot/quadruped_description/meshes/Assembly_lower_link_v2.stl</uri>
            </mesh>
          </geometry>
        </visual>
        <self_collide>0</self_collide>
        <enable_wind>0</enable_wind>
        <kinematic>0</kinematic>
      </link>
      <joint name='back_right_joint2' type='revolute'>
        <child>back_right_d</child>
        <parent>back_right_u</parent>
        <axis>
          <xyz>-0.001593 -0.999999 0</xyz>
          <limit>
            <lower>-3.14</lower>
            <upper>3.14</upper>
            <effort>1000</effort>
            <velocity>0.5</velocity>
          </limit>
          <dynamics>
            <spring_reference>0</spring_reference>
            <spring_stiffness>0</spring_stiffness>
          </dynamics>
          <use_parent_model_frame>1</use_parent_model_frame>
        </axis>
      </joint>
      <link name='front_left_u'>
        <pose frame=''>0.11 0.05 0 0 -0 0</pose>
        <inertial>
          <pose frame=''>0 0 0 0 -0 0</pose>
          <mass>1</mass>
          <inertia>
            <ixx>1</ixx>
            <ixy>0</ixy>
            <ixz>0</ixz>
            <iyy>1</iyy>
            <iyz>0</iyz>
            <izz>1</izz>
          </inertia>
        </inertial>
        <collision name='front_left_u_collision'>
          <pose frame=''>0 0 0 1.57 -0 1.57</pose>
          <geometry>
            <mesh>
              <scale>1 1 1</scale>
              <uri>/home/francisco/quadruped_ws/src/quadruped_robot/quadruped_description/meshes/joint_gear_upper_assembly.stl</uri>
            </mesh>
          </geometry>
          <max_contacts>10</max_contacts>
          <surface>
            <contact>
              <ode/>
            </contact>
            <bounce/>
            <friction>
              <torsional>
                <ode/>
              </torsional>
              <ode/>
            </friction>
          </surface>
        </collision>
        <visual name='front_left_u_visual'>
          <pose frame=''>0 0 0 1.57 -0 1.57</pose>
          <geometry>
            <mesh>
              <scale>1 1 1</scale>
              <uri>/home/francisco/quadruped_ws/src/quadruped_robot/quadruped_description/meshes/joint_gear_upper_assembly.stl</uri>
            </mesh>
          </geometry>
        </visual>
        <self_collide>0</self_collide>
        <enable_wind>0</enable_wind>
        <kinematic>0</kinematic>
      </link>
      <joint name='front_left_joint1' type='revolute'>
        <child>front_left_u</child>
        <parent>dummy</parent>
        <axis>
          <xyz>0 1 0</xyz>
          <limit>
            <lower>-3.14</lower>
            <upper>3.14</upper>
            <effort>1000</effort>
            <velocity>0.5</velocity>
          </limit>
          <dynamics>
            <spring_reference>0</spring_reference>
            <spring_stiffness>0</spring_stiffness>
          </dynamics>
          <use_parent_model_frame>1</use_parent_model_frame>
        </axis>
      </joint>
      <link name='front_left_d'>
        <pose frame=''>0.51 0.055 0 0 -0 0</pose>
        <inertial>
          <pose frame=''>0 0 0 0 -0 0</pose>
          <mass>1</mass>
          <inertia>
            <ixx>1</ixx>
            <ixy>0</ixy>
            <ixz>0</ixz>
            <iyy>1</iyy>
            <iyz>0</iyz>
            <izz>1</izz>
          </inertia>
        </inertial>
        <collision name='front_left_d_collision'>
          <pose frame=''>0 0 0 1.57 -0 1.57</pose>
          <geometry>
            <mesh>
              <scale>1 1 1</scale>
              <uri>/home/francisco/quadruped_ws/src/quadruped_robot/quadruped_description/meshes/Assembly_lower_link_v2.stl</uri>
            </mesh>
          </geometry>
          <max_contacts>10</max_contacts>
          <surface>
            <contact>
              <ode/>
            </contact>
            <bounce/>
            <friction>
              <torsional>
                <ode/>
              </torsional>
              <ode/>
            </friction>
          </surface>
        </collision>
        <visual name='front_left_d_visual'>
          <pose frame=''>0 0 0 1.57 -0 1.57</pose>
          <geometry>
            <mesh>
              <scale>1 1 1</scale>
              <uri>/home/francisco/quadruped_ws/src/quadruped_robot/quadruped_description/meshes/Assembly_lower_link_v2.stl</uri>
            </mesh>
          </geometry>
        </visual>
        <self_collide>0</self_collide>
        <enable_wind>0</enable_wind>
        <kinematic>0</kinematic>
      </link>
      <joint name='front_left_joint2' type='revolute'>
        <child>front_left_d</child>
        <parent>front_left_u</parent>
        <axis>
          <xyz>0 1 0</xyz>
          <limit>
            <lower>-3.14</lower>
            <upper>3.14</upper>
            <effort>1000</effort>
            <velocity>0.5</velocity>
          </limit>
          <dynamics>
            <spring_reference>0</spring_reference>
            <spring_stiffness>0</spring_stiffness>
          </dynamics>
          <use_parent_model_frame>1</use_parent_model_frame>
        </axis>
      </joint>
      <link name='front_right_u'>
        <pose frame=''>0.11 -0.05 0 0 -0 0</pose>
        <inertial>
          <pose frame=''>0 0 0 0 -0 0</pose>
          <mass>1</mass>
          <inertia>
            <ixx>1</ixx>
            <ixy>0</ixy>
            <ixz>0</ixz>
            <iyy>1</iyy>
            <iyz>0</iyz>
            <izz>1</izz>
          </inertia>
        </inertial>
        <collision name='front_right_u_collision'>
          <pose frame=''>0 0 0 -1.57159 0.001593 -1.57159</pose>
          <geometry>
            <mesh>
              <scale>1 1 1</scale>
              <uri>/home/francisco/quadruped_ws/src/quadruped_robot/quadruped_description/meshes/joint_gear_upper_assembly.stl</uri>
            </mesh>
          </geometry>
          <max_contacts>10</max_contacts>
          <surface>
            <contact>
              <ode/>
            </contact>
            <bounce/>
            <friction>
              <torsional>
                <ode/>
              </torsional>
              <ode/>
            </friction>
          </surface>
        </collision>
        <visual name='front_right_u_visual'>
          <pose frame=''>0 0 0 -1.57159 0.001593 -1.57159</pose>
          <geometry>
            <mesh>
              <scale>1 1 1</scale>
              <uri>/home/francisco/quadruped_ws/src/quadruped_robot/quadruped_description/meshes/joint_gear_upper_assembly.stl</uri>
            </mesh>
          </geometry>
        </visual>
        <self_collide>0</self_collide>
        <enable_wind>0</enable_wind>
        <kinematic>0</kinematic>
      </link>
      <joint name='front_right_joint1' type='revolute'>
        <child>front_right_u</child>
        <parent>dummy</parent>
        <axis>
          <xyz>0 1 0</xyz>
          <limit>
            <lower>-3.14</lower>
            <upper>3.14</upper>
            <effort>1000</effort>
            <velocity>0.5</velocity>
          </limit>
          <dynamics>
            <spring_reference>0</spring_reference>
            <spring_stiffness>0</spring_stiffness>
          </dynamics>
          <use_parent_model_frame>1</use_parent_model_frame>
        </axis>
      </joint>
      <link name='front_right_d'>
        <pose frame=''>0.51 -0.055 0 0 -0 0</pose>
        <inertial>
          <pose frame=''>0 0 0 0 -0 0</pose>
          <mass>1</mass>
          <inertia>
            <ixx>1</ixx>
            <ixy>0</ixy>
            <ixz>0</ixz>
            <iyy>1</iyy>
            <iyz>0</iyz>
            <izz>1</izz>
          </inertia>
        </inertial>
        <collision name='front_right_d_collision'>
          <pose frame=''>0 0 0 -1.57 -0 -1.57</pose>
          <geometry>
            <mesh>
              <scale>1 1 1</scale>
              <uri>/home/francisco/quadruped_ws/src/quadruped_robot/quadruped_description/meshes/Assembly_lower_link_v2.stl</uri>
            </mesh>
          </geometry>
          <max_contacts>10</max_contacts>
          <surface>
            <contact>
              <ode/>
            </contact>
            <bounce/>
            <friction>
              <torsional>
                <ode/>
              </torsional>
              <ode/>
            </friction>
          </surface>
        </collision>
        <visual name='front_right_d_visual'>
          <pose frame=''>0 0 0 -1.57 -0 -1.57</pose>
          <geometry>
            <mesh>
              <scale>1 1 1</scale>
              <uri>/home/francisco/quadruped_ws/src/quadruped_robot/quadruped_description/meshes/Assembly_lower_link_v2.stl</uri>
            </mesh>
          </geometry>
        </visual>
        <self_collide>0</self_collide>
        <enable_wind>0</enable_wind>
        <kinematic>0</kinematic>
      </link>
      <joint name='front_right_joint2' type='revolute'>
        <child>front_right_d</child>
        <parent>front_right_u</parent>
        <axis>
          <xyz>0 1 0</xyz>
          <limit>
            <lower>-3.14</lower>
            <upper>3.14</upper>
            <effort>1000</effort>
            <velocity>0.5</velocity>
          </limit>
          <dynamics>
            <spring_reference>0</spring_reference>
            <spring_stiffness>0</spring_stiffness>
          </dynamics>
          <use_parent_model_frame>1</use_parent_model_frame>
        </axis>
      </joint>
      <static>0</static>
      <plugin name='gazebo_ros_control' filename='libgazebo_ros_control.so'>
        <robotNamespace>/quadruped</robotNamespace>
      </plugin>
      <pose frame=''>0 0 0.0615 0 -0 0</pose>
    </model>
    <model name='cardboard_box'>
      <pose frame=''>-1.03488 1.86845 0.15 0 -0 0</pose>
      <link name='link'>
        <inertial>
          <mass>2</mass>
          <inertia>
            <ixx>0.0416667</ixx>
            <ixy>0</ixy>
            <ixz>0</ixz>
            <iyy>0.0566667</iyy>
            <iyz>0</iyz>
            <izz>0.0683333</izz>
          </inertia>
        </inertial>
        <collision name='collision'>
          <geometry>
            <box>
              <size>0.5 0.4 0.3</size>
            </box>
          </geometry>
          <surface>
            <friction>
              <ode>
                <mu>1</mu>
                <mu2>1</mu2>
              </ode>
              <torsional>
                <ode/>
              </torsional>
            </friction>
            <contact>
              <ode>
                <kp>1e+07</kp>
                <kd>1</kd>
                <min_depth>0.001</min_depth>
                <max_vel>0.1</max_vel>
              </ode>
            </contact>
            <bounce/>
          </surface>
          <max_contacts>10</max_contacts>
        </collision>
        <visual name='visual'>
          <pose frame=''>0 0 -0.15 0 -0 0</pose>
          <geometry>
            <mesh>
              <uri>model://cardboard_box/meshes/cardboard_box.dae</uri>
              <scale>1.25932 1.00745 0.755591</scale>
            </mesh>
          </geometry>
        </visual>
        <self_collide>0</self_collide>
        <enable_wind>0</enable_wind>
        <kinematic>0</kinematic>
      </link>
    </model>
    <model name='grey_tote'>
      <link name='link'>
        <inertial>
          <pose frame=''>0 0 0.14155 0 -0 0</pose>
          <mass>3.53802</mass>
          <inertia>
            <ixx>0.0688358</ixx>
            <ixy>0</ixy>
            <ixz>0</ixz>
            <iyy>0.139596</iyy>
            <iyz>0</iyz>
            <izz>0.155909</izz>
          </inertia>
        </inertial>
        <collision name='lid'>
          <pose frame=''>0 0 0.28958 0 -0 0</pose>
          <geometry>
            <box>
              <size>0.67768 0.41298 0.01588</size>
            </box>
          </geometry>
          <max_contacts>10</max_contacts>
          <surface>
            <contact>
              <ode/>
            </contact>
            <bounce/>
            <friction>
              <torsional>
                <ode/>
              </torsional>
              <ode/>
            </friction>
          </surface>
        </collision>
        <collision name='lid_lip_1'>
          <pose frame=''>0 0.20063 0.3048 0 -0 0</pose>
          <geometry>
            <box>
              <size>0.65068 0.0105 0.0127</size>
            </box>
          </geometry>
          <max_contacts>10</max_contacts>
          <surface>
            <contact>
              <ode/>
            </contact>
            <bounce/>
            <friction>
              <torsional>
                <ode/>
              </torsional>
              <ode/>
            </friction>
          </surface>
        </collision>
        <collision name='lid_lip_2'>
          <pose frame=''>0 -0.20063 0.3048 0 -0 0</pose>
          <geometry>
            <box>
              <size>0.65068 0.0105 0.0127</size>
            </box>
          </geometry>
          <max_contacts>10</max_contacts>
          <surface>
            <contact>
              <ode/>
            </contact>
            <bounce/>
            <friction>
              <torsional>
                <ode/>
              </torsional>
              <ode/>
            </friction>
          </surface>
        </collision>
        <collision name='lid_lip_3'>
          <pose frame=''>0.32585 0 0.3048 0 -0 0</pose>
          <geometry>
            <box>
              <size>0.02602 0.31202 0.0127</size>
            </box>
          </geometry>
          <max_contacts>10</max_contacts>
          <surface>
            <contact>
              <ode/>
            </contact>
            <bounce/>
            <friction>
              <torsional>
                <ode/>
              </torsional>
              <ode/>
            </friction>
          </surface>
        </collision>
        <collision name='lid_lip_4'>
          <pose frame=''>-0.32585 0 0.3048 0 -0 0</pose>
          <geometry>
            <box>
              <size>0.02602 0.31202 0.0127</size>
            </box>
          </geometry>
          <max_contacts>10</max_contacts>
          <surface>
            <contact>
              <ode/>
            </contact>
            <bounce/>
            <friction>
              <torsional>
                <ode/>
              </torsional>
              <ode/>
            </friction>
          </surface>
        </collision>
        <collision name='side_wall_1'>
          <pose frame=''>0 -0.18 0.14155 0.061147 -0 0</pose>
          <geometry>
            <box>
              <size>0.58404 0.02602 0.283099</size>
            </box>
          </geometry>
          <max_contacts>10</max_contacts>
          <surface>
            <contact>
              <ode/>
            </contact>
            <bounce/>
            <friction>
              <torsional>
                <ode/>
              </torsional>
              <ode/>
            </friction>
          </surface>
        </collision>
        <collision name='side_wall_2'>
          <pose frame=''>0 0.18 0.14155 -0.061147 0 0</pose>
          <geometry>
            <box>
              <size>0.58404 0.02602 0.283099</size>
            </box>
          </geometry>
          <max_contacts>10</max_contacts>
          <surface>
            <contact>
              <ode/>
            </contact>
            <bounce/>
            <friction>
              <torsional>
                <ode/>
              </torsional>
              <ode/>
            </friction>
          </surface>
        </collision>
        <collision name='side_wall_3'>
          <pose frame=''>0.305 0 0.14155 0 0.061147 0</pose>
          <geometry>
            <box>
              <size>0.02602 0.33046 0.283099</size>
            </box>
          </geometry>
          <max_contacts>10</max_contacts>
          <surface>
            <contact>
              <ode/>
            </contact>
            <bounce/>
            <friction>
              <torsional>
                <ode/>
              </torsional>
              <ode/>
            </friction>
          </surface>
        </collision>
        <collision name='side_wall_4'>
          <pose frame=''>-0.305 0 0.14155 0 -0.061147 0</pose>
          <geometry>
            <box>
              <size>0.02602 0.33046 0.283099</size>
            </box>
          </geometry>
          <max_contacts>10</max_contacts>
          <surface>
            <contact>
              <ode/>
            </contact>
            <bounce/>
            <friction>
              <torsional>
                <ode/>
              </torsional>
              <ode/>
            </friction>
          </surface>
        </collision>
        <collision name='bottom'>
          <pose frame=''>0 0 0.01 0 -0 0</pose>
          <geometry>
            <box>
              <size>0.58404 0.33046 0.02</size>
            </box>
          </geometry>
          <max_contacts>10</max_contacts>
          <surface>
            <contact>
              <ode/>
            </contact>
            <bounce/>
            <friction>
              <torsional>
                <ode/>
              </torsional>
              <ode/>
            </friction>
          </surface>
        </collision>
        <collision name='corner_1'>
          <pose frame=''>0.30202 -0.175 0.14155 0.061147 0.061147 -0</pose>
          <geometry>
            <cylinder>
              <radius>0.01268</radius>
              <length>0.283099</length>
            </cylinder>
          </geometry>
          <max_contacts>10</max_contacts>
          <surface>
            <contact>
              <ode/>
            </contact>
            <bounce/>
            <friction>
              <torsional>
                <ode/>
              </torsional>
              <ode/>
            </friction>
          </surface>
        </collision>
        <collision name='corner_2'>
          <pose frame=''>-0.30202 -0.175 0.14155 0.061147 -0.061147 0</pose>
          <geometry>
            <cylinder>
              <radius>0.01268</radius>
              <length>0.283099</length>
            </cylinder>
          </geometry>
          <max_contacts>10</max_contacts>
          <surface>
            <contact>
              <ode/>
            </contact>
            <bounce/>
            <friction>
              <torsional>
                <ode/>
              </torsional>
              <ode/>
            </friction>
          </surface>
        </collision>
        <collision name='corner_3'>
          <pose frame=''>-0.30202 0.175 0.14155 -0.061147 -0.061147 -0</pose>
          <geometry>
            <cylinder>
              <radius>0.01268</radius>
              <length>0.283099</length>
            </cylinder>
          </geometry>
          <max_contacts>10</max_contacts>
          <surface>
            <contact>
              <ode/>
            </contact>
            <bounce/>
            <friction>
              <torsional>
                <ode/>
              </torsional>
              <ode/>
            </friction>
          </surface>
        </collision>
        <collision name='corner_4'>
          <pose frame=''>0.30202 0.175 0.14155 -0.061147 0.061147 0</pose>
          <geometry>
            <cylinder>
              <radius>0.01268</radius>
              <length>0.283099</length>
            </cylinder>
          </geometry>
          <max_contacts>10</max_contacts>
          <surface>
            <contact>
              <ode/>
            </contact>
            <bounce/>
            <friction>
              <torsional>
                <ode/>
              </torsional>
              <ode/>
            </friction>
          </surface>
        </collision>
        <visual name='visual'>
          <geometry>
            <mesh>
              <uri>model://grey_tote/meshes/tote.dae</uri>
            </mesh>
          </geometry>
        </visual>
        <self_collide>0</self_collide>
        <enable_wind>0</enable_wind>
        <kinematic>0</kinematic>
      </link>
      <pose frame=''>0.079128 1.7976 0 0 -0 0</pose>
    </model>
    <model name='grey_wall'>
      <static>1</static>
      <link name='link'>
        <pose frame=''>0 0 1.4 0 -0 0</pose>
        <collision name='collision'>
          <geometry>
            <box>
              <size>7.5 0.2 2.8</size>
            </box>
          </geometry>
          <max_contacts>10</max_contacts>
          <surface>
            <contact>
              <ode/>
            </contact>
            <bounce/>
            <friction>
              <torsional>
                <ode/>
              </torsional>
              <ode/>
            </friction>
          </surface>
        </collision>
        <visual name='visual'>
          <cast_shadows>0</cast_shadows>
          <geometry>
            <box>
              <size>7.5 0.2 2.8</size>
            </box>
          </geometry>
          <material>
            <script>
              <uri>model://grey_wall/materials/scripts</uri>
              <uri>model://grey_wall/materials/textures</uri>
              <name>vrc/grey_wall</name>
            </script>
          </material>
        </visual>
        <self_collide>0</self_collide>
        <enable_wind>0</enable_wind>
        <kinematic>0</kinematic>
      </link>
      <pose frame=''>-0.061412 3.1632 0 0 -0 0</pose>
    </model>
    <model name='ladder_60deg_1rails'>
      <static>1</static>
      <link name='step0'>
        <pose frame=''>0 0.15396 0.266667 0 -0 0</pose>
        <inertial>
          <mass>9.75482</mass>
          <inertia>
            <ixx>0.00957124</ixx>
            <iyy>0.65963</iyy>
            <izz>0.666842</izz>
            <ixy>0</ixy>
            <ixz>0</ixz>
            <iyz>0</iyz>
          </inertia>
        </inertial>
        <collision name='collision'>
          <geometry>
            <box>
              <size>0.9 0.1016 0.0381</size>
            </box>
          </geometry>
          <max_contacts>10</max_contacts>
          <surface>
            <contact>
              <ode/>
            </contact>
            <bounce/>
            <friction>
              <torsional>
                <ode/>
              </torsional>
              <ode/>
            </friction>
          </surface>
        </collision>
        <visual name='visual'>
          <geometry>
            <box>
              <size>0.9 0.1016 0.0381</size>
            </box>
          </geometry>
          <material>
            <script>
              <uri>file://media/materials/scripts/gazebo.material</uri>
              <name>Gazebo/Grey</name>
            </script>
          </material>
        </visual>
        <self_collide>0</self_collide>
        <enable_wind>0</enable_wind>
        <kinematic>0</kinematic>
      </link>
      <link name='step1'>
        <pose frame=''>0 0.30792 0.533333 0 -0 0</pose>
        <inertial>
          <mass>9.75482</mass>
          <inertia>
            <ixx>0.00957124</ixx>
            <iyy>0.65963</iyy>
            <izz>0.666842</izz>
            <ixy>0</ixy>
            <ixz>0</ixz>
            <iyz>0</iyz>
          </inertia>
        </inertial>
        <collision name='collision'>
          <geometry>
            <box>
              <size>0.9 0.1016 0.0381</size>
            </box>
          </geometry>
          <max_contacts>10</max_contacts>
          <surface>
            <contact>
              <ode/>
            </contact>
            <bounce/>
            <friction>
              <torsional>
                <ode/>
              </torsional>
              <ode/>
            </friction>
          </surface>
        </collision>
        <visual name='visual'>
          <geometry>
            <box>
              <size>0.9 0.1016 0.0381</size>
            </box>
          </geometry>
          <material>
            <script>
              <uri>file://media/materials/scripts/gazebo.material</uri>
              <name>Gazebo/Grey</name>
            </script>
          </material>
        </visual>
        <self_collide>0</self_collide>
        <enable_wind>0</enable_wind>
        <kinematic>0</kinematic>
      </link>
      <link name='step2'>
        <pose frame=''>0 0.46188 0.8 0 -0 0</pose>
        <inertial>
          <mass>9.75482</mass>
          <inertia>
            <ixx>0.00957124</ixx>
            <iyy>0.65963</iyy>
            <izz>0.666842</izz>
            <ixy>0</ixy>
            <ixz>0</ixz>
            <iyz>0</iyz>
          </inertia>
        </inertial>
        <collision name='collision'>
          <geometry>
            <box>
              <size>0.9 0.1016 0.0381</size>
            </box>
          </geometry>
          <max_contacts>10</max_contacts>
          <surface>
            <contact>
              <ode/>
            </contact>
            <bounce/>
            <friction>
              <torsional>
                <ode/>
              </torsional>
              <ode/>
            </friction>
          </surface>
        </collision>
        <visual name='visual'>
          <geometry>
            <box>
              <size>0.9 0.1016 0.0381</size>
            </box>
          </geometry>
          <material>
            <script>
              <uri>file://media/materials/scripts/gazebo.material</uri>
              <name>Gazebo/Grey</name>
            </script>
          </material>
        </visual>
        <self_collide>0</self_collide>
        <enable_wind>0</enable_wind>
        <kinematic>0</kinematic>
      </link>
      <link name='step3'>
        <pose frame=''>0 0.61584 1.06667 0 -0 0</pose>
        <inertial>
          <mass>9.75482</mass>
          <inertia>
            <ixx>0.00957124</ixx>
            <iyy>0.65963</iyy>
            <izz>0.666842</izz>
            <ixy>0</ixy>
            <ixz>0</ixz>
            <iyz>0</iyz>
          </inertia>
        </inertial>
        <collision name='collision'>
          <geometry>
            <box>
              <size>0.9 0.1016 0.0381</size>
            </box>
          </geometry>
          <max_contacts>10</max_contacts>
          <surface>
            <contact>
              <ode/>
            </contact>
            <bounce/>
            <friction>
              <torsional>
                <ode/>
              </torsional>
              <ode/>
            </friction>
          </surface>
        </collision>
        <visual name='visual'>
          <geometry>
            <box>
              <size>0.9 0.1016 0.0381</size>
            </box>
          </geometry>
          <material>
            <script>
              <uri>file://media/materials/scripts/gazebo.material</uri>
              <name>Gazebo/Grey</name>
            </script>
          </material>
        </visual>
        <self_collide>0</self_collide>
        <enable_wind>0</enable_wind>
        <kinematic>0</kinematic>
      </link>
      <link name='step4'>
        <pose frame=''>0 0.7698 1.33333 0 -0 0</pose>
        <inertial>
          <mass>9.75482</mass>
          <inertia>
            <ixx>0.00957124</ixx>
            <iyy>0.65963</iyy>
            <izz>0.666842</izz>
            <ixy>0</ixy>
            <ixz>0</ixz>
            <iyz>0</iyz>
          </inertia>
        </inertial>
        <collision name='collision'>
          <geometry>
            <box>
              <size>0.9 0.1016 0.0381</size>
            </box>
          </geometry>
          <max_contacts>10</max_contacts>
          <surface>
            <contact>
              <ode/>
            </contact>
            <bounce/>
            <friction>
              <torsional>
                <ode/>
              </torsional>
              <ode/>
            </friction>
          </surface>
        </collision>
        <visual name='visual'>
          <geometry>
            <box>
              <size>0.9 0.1016 0.0381</size>
            </box>
          </geometry>
          <material>
            <script>
              <uri>file://media/materials/scripts/gazebo.material</uri>
              <name>Gazebo/Grey</name>
            </script>
          </material>
        </visual>
        <self_collide>0</self_collide>
        <enable_wind>0</enable_wind>
        <kinematic>0</kinematic>
      </link>
      <link name='step5'>
        <pose frame=''>0 0.92376 1.6 0 -0 0</pose>
        <inertial>
          <mass>9.75482</mass>
          <inertia>
            <ixx>0.00957124</ixx>
            <iyy>0.65963</iyy>
            <izz>0.666842</izz>
            <ixy>0</ixy>
            <ixz>0</ixz>
            <iyz>0</iyz>
          </inertia>
        </inertial>
        <collision name='collision'>
          <geometry>
            <box>
              <size>0.9 0.1016 0.0381</size>
            </box>
          </geometry>
          <max_contacts>10</max_contacts>
          <surface>
            <contact>
              <ode/>
            </contact>
            <bounce/>
            <friction>
              <torsional>
                <ode/>
              </torsional>
              <ode/>
            </friction>
          </surface>
        </collision>
        <visual name='visual'>
          <geometry>
            <box>
              <size>0.9 0.1016 0.0381</size>
            </box>
          </geometry>
          <material>
            <script>
              <uri>file://media/materials/scripts/gazebo.material</uri>
              <name>Gazebo/Grey</name>
            </script>
          </material>
        </visual>
        <self_collide>0</self_collide>
        <enable_wind>0</enable_wind>
        <kinematic>0</kinematic>
      </link>
      <link name='step6'>
        <pose frame=''>0 1.07772 1.86667 0 -0 0</pose>
        <inertial>
          <mass>9.75482</mass>
          <inertia>
            <ixx>0.00957124</ixx>
            <iyy>0.65963</iyy>
            <izz>0.666842</izz>
            <ixy>0</ixy>
            <ixz>0</ixz>
            <iyz>0</iyz>
          </inertia>
        </inertial>
        <collision name='collision'>
          <geometry>
            <box>
              <size>0.9 0.1016 0.0381</size>
            </box>
          </geometry>
          <max_contacts>10</max_contacts>
          <surface>
            <contact>
              <ode/>
            </contact>
            <bounce/>
            <friction>
              <torsional>
                <ode/>
              </torsional>
              <ode/>
            </friction>
          </surface>
        </collision>
        <visual name='visual'>
          <geometry>
            <box>
              <size>0.9 0.1016 0.0381</size>
            </box>
          </geometry>
          <material>
            <script>
              <uri>file://media/materials/scripts/gazebo.material</uri>
              <name>Gazebo/Grey</name>
            </script>
          </material>
        </visual>
        <self_collide>0</self_collide>
        <enable_wind>0</enable_wind>
        <kinematic>0</kinematic>
      </link>
      <link name='step7'>
        <pose frame=''>0 1.23168 2.13333 0 -0 0</pose>
        <inertial>
          <mass>9.75482</mass>
          <inertia>
            <ixx>0.00957124</ixx>
            <iyy>0.65963</iyy>
            <izz>0.666842</izz>
            <ixy>0</ixy>
            <ixz>0</ixz>
            <iyz>0</iyz>
          </inertia>
        </inertial>
        <collision name='collision'>
          <geometry>
            <box>
              <size>0.9 0.1016 0.0381</size>
            </box>
          </geometry>
          <max_contacts>10</max_contacts>
          <surface>
            <contact>
              <ode/>
            </contact>
            <bounce/>
            <friction>
              <torsional>
                <ode/>
              </torsional>
              <ode/>
            </friction>
          </surface>
        </collision>
        <visual name='visual'>
          <geometry>
            <box>
              <size>0.9 0.1016 0.0381</size>
            </box>
          </geometry>
          <material>
            <script>
              <uri>file://media/materials/scripts/gazebo.material</uri>
              <name>Gazebo/Grey</name>
            </script>
          </material>
        </visual>
        <self_collide>0</self_collide>
        <enable_wind>0</enable_wind>
        <kinematic>0</kinematic>
      </link>
      <link name='landing'>
        <pose frame=''>0 1.68564 2.4 0 -0 0</pose>
        <inertial>
          <mass>57.6072</mass>
          <inertia>
            <ixx>1.73518</ixx>
            <iyy>3.89545</iyy>
            <izz>5.6167</izz>
            <ixy>0</ixy>
            <ixz>0</ixz>
            <iyz>0</iyz>
          </inertia>
        </inertial>
        <collision name='collision'>
          <geometry>
            <box>
              <size>0.9 0.6 0.1016</size>
            </box>
          </geometry>
          <max_contacts>10</max_contacts>
          <surface>
            <contact>
              <ode/>
            </contact>
            <bounce/>
            <friction>
              <torsional>
                <ode/>
              </torsional>
              <ode/>
            </friction>
          </surface>
        </collision>
        <visual name='visual'>
          <geometry>
            <box>
              <size>0.9 0.6 0.1016</size>
            </box>
          </geometry>
          <material>
            <script>
              <uri>file://media/materials/scripts/gazebo.material</uri>
              <name>Gazebo/Grey</name>
            </script>
          </material>
        </visual>
        <self_collide>0</self_collide>
        <enable_wind>0</enable_wind>
        <kinematic>0</kinematic>
      </link>
      <link name='left_side_wall'>
        <pose frame=''>-0.45 0.69282 1.2 1.0472 -0 0</pose>
        <collision name='collision'>
          <geometry>
            <box>
              <size>0.0508 2.85128 0.13</size>
            </box>
          </geometry>
          <max_contacts>10</max_contacts>
          <surface>
            <contact>
              <ode/>
            </contact>
            <bounce/>
            <friction>
              <torsional>
                <ode/>
              </torsional>
              <ode/>
            </friction>
          </surface>
        </collision>
        <visual name='visual'>
          <geometry>
            <box>
              <size>0.0508 2.85128 0.13</size>
            </box>
          </geometry>
          <material>
            <script>
              <uri>file://media/materials/scripts/gazebo.material</uri>
              <name>Gazebo/Grey</name>
            </script>
          </material>
        </visual>
        <self_collide>0</self_collide>
        <enable_wind>0</enable_wind>
        <kinematic>0</kinematic>
      </link>
      <link name='right_side_wall'>
        <pose frame=''>0.45 0.69282 1.2 1.0472 -0 0</pose>
        <collision name='collision'>
          <geometry>
            <box>
              <size>0.0508 2.85128 0.13</size>
            </box>
          </geometry>
          <max_contacts>10</max_contacts>
          <surface>
            <contact>
              <ode/>
            </contact>
            <bounce/>
            <friction>
              <torsional>
                <ode/>
              </torsional>
              <ode/>
            </friction>
          </surface>
        </collision>
        <visual name='visual'>
          <geometry>
            <box>
              <size>0.0508 2.85128 0.13</size>
            </box>
          </geometry>
          <material>
            <script>
              <uri>file://media/materials/scripts/gazebo.material</uri>
              <name>Gazebo/Grey</name>
            </script>
          </material>
        </visual>
        <self_collide>0</self_collide>
        <enable_wind>0</enable_wind>
        <kinematic>0</kinematic>
      </link>
      <link name='left_railing_long'>
        <pose frame=''>-0.45 0.34282 1.80622 -0.523599 0 0</pose>
        <collision name='collision'>
          <geometry>
            <cylinder>
              <radius>0.02413</radius>
              <length>4.17128</length>
            </cylinder>
          </geometry>
          <max_contacts>10</max_contacts>
          <surface>
            <contact>
              <ode/>
            </contact>
            <bounce/>
            <friction>
              <torsional>
                <ode/>
              </torsional>
              <ode/>
            </friction>
          </surface>
        </collision>
        <visual name='visual'>
          <geometry>
            <cylinder>
              <radius>0.02413</radius>
              <length>4.17128</length>
            </cylinder>
          </geometry>
          <material>
            <script>
              <uri>file://media/materials/scripts/gazebo.material</uri>
              <name>Gazebo/Grey</name>
            </script>
          </material>
        </visual>
        <self_collide>0</self_collide>
        <enable_wind>0</enable_wind>
        <kinematic>0</kinematic>
      </link>
      <link name='left_railing_upright0'>
        <pose frame=''>-0.45 -0.274963 0.15875 1.0472 -0 0</pose>
        <collision name='collision'>
          <geometry>
            <cylinder>
              <radius>0.02413</radius>
              <length>0.541218</length>
            </cylinder>
          </geometry>
          <max_contacts>10</max_contacts>
          <surface>
            <contact>
              <ode/>
            </contact>
            <bounce/>
            <friction>
              <torsional>
                <ode/>
              </torsional>
              <ode/>
            </friction>
          </surface>
        </collision>
        <visual name='visual'>
          <geometry>
            <cylinder>
              <radius>0.02413</radius>
              <length>0.541218</length>
            </cylinder>
          </geometry>
          <material>
            <script>
              <uri>file://media/materials/scripts/gazebo.material</uri>
              <name>Gazebo/Grey</name>
            </script>
          </material>
        </visual>
        <self_collide>0</self_collide>
        <enable_wind>0</enable_wind>
        <kinematic>0</kinematic>
      </link>
      <link name='left_railing_upright1'>
        <pose frame=''>-0.45 0.186917 0.95875 1.0472 -0 0</pose>
        <collision name='collision'>
          <geometry>
            <cylinder>
              <radius>0.02413</radius>
              <length>0.541218</length>
            </cylinder>
          </geometry>
          <max_contacts>10</max_contacts>
          <surface>
            <contact>
              <ode/>
            </contact>
            <bounce/>
            <friction>
              <torsional>
                <ode/>
              </torsional>
              <ode/>
            </friction>
          </surface>
        </collision>
        <visual name='visual'>
          <geometry>
            <cylinder>
              <radius>0.02413</radius>
              <length>0.541218</length>
            </cylinder>
          </geometry>
          <material>
            <script>
              <uri>file://media/materials/scripts/gazebo.material</uri>
              <name>Gazebo/Grey</name>
            </script>
          </material>
        </visual>
        <self_collide>0</self_collide>
        <enable_wind>0</enable_wind>
        <kinematic>0</kinematic>
      </link>
      <link name='left_railing_upright2'>
        <pose frame=''>-0.45 0.648797 1.75875 1.0472 -0 0</pose>
        <collision name='collision'>
          <geometry>
            <cylinder>
              <radius>0.02413</radius>
              <length>0.541218</length>
            </cylinder>
          </geometry>
          <max_contacts>10</max_contacts>
          <surface>
            <contact>
              <ode/>
            </contact>
            <bounce/>
            <friction>
              <torsional>
                <ode/>
              </torsional>
              <ode/>
            </friction>
          </surface>
        </collision>
        <visual name='visual'>
          <geometry>
            <cylinder>
              <radius>0.02413</radius>
              <length>0.541218</length>
            </cylinder>
          </geometry>
          <material>
            <script>
              <uri>file://media/materials/scripts/gazebo.material</uri>
              <name>Gazebo/Grey</name>
            </script>
          </material>
        </visual>
        <self_collide>0</self_collide>
        <enable_wind>0</enable_wind>
        <kinematic>0</kinematic>
      </link>
      <link name='left_railing_upright3'>
        <pose frame=''>-0.45 1.11068 2.55875 1.0472 -0 0</pose>
        <collision name='collision'>
          <geometry>
            <cylinder>
              <radius>0.02413</radius>
              <length>0.541218</length>
            </cylinder>
          </geometry>
          <max_contacts>10</max_contacts>
          <surface>
            <contact>
              <ode/>
            </contact>
            <bounce/>
            <friction>
              <torsional>
                <ode/>
              </torsional>
              <ode/>
            </friction>
          </surface>
        </collision>
        <visual name='visual'>
          <geometry>
            <cylinder>
              <radius>0.02413</radius>
              <length>0.541218</length>
            </cylinder>
          </geometry>
          <material>
            <script>
              <uri>file://media/materials/scripts/gazebo.material</uri>
              <name>Gazebo/Grey</name>
            </script>
          </material>
        </visual>
        <self_collide>0</self_collide>
        <enable_wind>0</enable_wind>
        <kinematic>0</kinematic>
      </link>
      <link name='left_railing_landing_top'>
        <pose frame=''>-0.45 1.68564 3.61244 1.5708 -0 0</pose>
        <collision name='collision'>
          <geometry>
            <cylinder>
              <radius>0.02413</radius>
              <length>0.64826</length>
            </cylinder>
          </geometry>
          <max_contacts>10</max_contacts>
          <surface>
            <contact>
              <ode/>
            </contact>
            <bounce/>
            <friction>
              <torsional>
                <ode/>
              </torsional>
              <ode/>
            </friction>
          </surface>
        </collision>
        <visual name='visual'>
          <geometry>
            <cylinder>
              <radius>0.02413</radius>
              <length>0.64826</length>
            </cylinder>
          </geometry>
          <material>
            <script>
              <uri>file://media/materials/scripts/gazebo.material</uri>
              <name>Gazebo/Grey</name>
            </script>
          </material>
        </visual>
        <self_collide>0</self_collide>
        <enable_wind>0</enable_wind>
        <kinematic>0</kinematic>
      </link>
      <link name='left_railing_landing_upright_0'>
        <pose frame=''>-0.45 1.38564 3.00622 0 -0 0</pose>
        <collision name='collision'>
          <geometry>
            <cylinder>
              <radius>0.02413</radius>
              <length>1.21244</length>
            </cylinder>
          </geometry>
          <max_contacts>10</max_contacts>
          <surface>
            <contact>
              <ode/>
            </contact>
            <bounce/>
            <friction>
              <torsional>
                <ode/>
              </torsional>
              <ode/>
            </friction>
          </surface>
        </collision>
        <visual name='visual'>
          <geometry>
            <cylinder>
              <radius>0.02413</radius>
              <length>1.21244</length>
            </cylinder>
          </geometry>
          <material>
            <script>
              <uri>file://media/materials/scripts/gazebo.material</uri>
              <name>Gazebo/Grey</name>
            </script>
          </material>
        </visual>
        <self_collide>0</self_collide>
        <enable_wind>0</enable_wind>
        <kinematic>0</kinematic>
      </link>
      <link name='left_railing_landing_upright_1'>
        <pose frame=''>-0.45 1.98564 3.00622 0 -0 0</pose>
        <collision name='collision'>
          <geometry>
            <cylinder>
              <radius>0.02413</radius>
              <length>1.21244</length>
            </cylinder>
          </geometry>
          <max_contacts>10</max_contacts>
          <surface>
            <contact>
              <ode/>
            </contact>
            <bounce/>
            <friction>
              <torsional>
                <ode/>
              </torsional>
              <ode/>
            </friction>
          </surface>
        </collision>
        <visual name='visual'>
          <geometry>
            <cylinder>
              <radius>0.02413</radius>
              <length>1.21244</length>
            </cylinder>
          </geometry>
          <material>
            <script>
              <uri>file://media/materials/scripts/gazebo.material</uri>
              <name>Gazebo/Grey</name>
            </script>
          </material>
        </visual>
        <self_collide>0</self_collide>
        <enable_wind>0</enable_wind>
        <kinematic>0</kinematic>
      </link>
      <pose frame=''>3.04448 0.636565 0 0 -0 0</pose>
    </model>
    <model name='nist_stairs_120'>
      <static>1</static>
      <link name='nist_stairs_120_link'>
        <pose frame=''>0 0 0 0 -0 0</pose>
        <collision name='collision'>
          <geometry>
            <mesh>
              <uri>model://nist_stairs_120/meshes/nist_stairs_120.dae</uri>
              <scale>1 1 1</scale>
            </mesh>
          </geometry>
          <max_contacts>10</max_contacts>
          <surface>
            <contact>
              <ode/>
            </contact>
            <bounce/>
            <friction>
              <torsional>
                <ode/>
              </torsional>
              <ode/>
            </friction>
          </surface>
        </collision>
        <visual name='visual'>
          <geometry>
            <mesh>
              <uri>model://nist_stairs_120/meshes/nist_stairs_120.dae</uri>
              <scale>1 1 1</scale>
            </mesh>
          </geometry>
        </visual>
        <self_collide>0</self_collide>
        <enable_wind>0</enable_wind>
        <kinematic>0</kinematic>
      </link>
      <pose frame=''>-2.54645 0.386562 0 0 -0 0</pose>
    </model>
    <state world_name='default'>
      <sim_time>240 500000000</sim_time>
      <real_time>917 494130514</real_time>
      <wall_time>1585034590 650175080</wall_time>
      <iterations>240500</iterations>
      <model name='cardboard_box'>
        <pose frame=''>-1.03488 1.86845 0.149 0 -0 0</pose>
        <scale>1 1 1</scale>
        <link name='link'>
          <pose frame=''>-1.03488 1.86845 0.149 0 -0 0</pose>
          <velocity>0 0 0 0 -0 0</velocity>
          <acceleration>0 -1.9e-05 0 0.000128 2e-06 0</acceleration>
          <wrench>1e-06 -3.8e-05 1e-06 0 -0 0</wrench>
        </link>
      </model>
      <model name='grey_tote'>
        <pose frame=''>0.079128 1.7976 0.000566 0 -0 0</pose>
        <scale>1 1 1</scale>
        <link name='link'>
          <pose frame=''>0.079128 1.7976 0.000566 0 -0 0</pose>
          <velocity>0 0 0 0 -0 0</velocity>
          <acceleration>0 0 0 0 -0 0</acceleration>
          <wrench>0 0 0 0 -0 0</wrench>
        </link>
      </model>
      <model name='grey_wall'>
        <pose frame=''>-0.061412 3.1632 0 0 -0 0</pose>
        <scale>1 1 1</scale>
        <link name='link'>
          <pose frame=''>-0.061412 3.1632 1.4 0 -0 0</pose>
          <velocity>0 0 0 0 -0 0</velocity>
          <acceleration>0 0 0 0 -0 0</acceleration>
          <wrench>0 0 0 0 -0 0</wrench>
        </link>
      </model>
      <model name='ground_plane'>
        <pose frame=''>0 0 0 0 -0 0</pose>
        <scale>1 1 1</scale>
        <link name='link'>
          <pose frame=''>0 0 0 0 -0 0</pose>
          <velocity>0 0 0 0 -0 0</velocity>
          <acceleration>0 0 0 0 -0 0</acceleration>
          <wrench>0 0 0 0 -0 0</wrench>
        </link>
      </model>
      <model name='ladder_60deg_1rails'>
        <pose frame=''>3.04448 0.636565 0 0 -0 0</pose>
        <scale>1 1 1</scale>
        <link name='landing'>
          <pose frame=''>3.04448 2.3222 2.4 0 -0 0</pose>
          <velocity>0 0 0 0 -0 0</velocity>
          <acceleration>0 0 0 0 -0 0</acceleration>
          <wrench>0 0 0 0 -0 0</wrench>
        </link>
        <link name='left_railing_landing_top'>
          <pose frame=''>2.59448 2.3222 3.61244 1.5708 -0 0</pose>
          <velocity>0 0 0 0 -0 0</velocity>
          <acceleration>0 0 0 0 -0 0</acceleration>
          <wrench>0 0 0 0 -0 0</wrench>
        </link>
        <link name='left_railing_landing_upright_0'>
          <pose frame=''>2.59448 2.02221 3.00622 0 -0 0</pose>
          <velocity>0 0 0 0 -0 0</velocity>
          <acceleration>0 0 0 0 -0 0</acceleration>
          <wrench>0 0 0 0 -0 0</wrench>
        </link>
        <link name='left_railing_landing_upright_1'>
          <pose frame=''>2.59448 2.62221 3.00622 0 -0 0</pose>
          <velocity>0 0 0 0 -0 0</velocity>
          <acceleration>0 0 0 0 -0 0</acceleration>
          <wrench>0 0 0 0 -0 0</wrench>
        </link>
        <link name='left_railing_long'>
          <pose frame=''>2.59448 0.979385 1.80622 -0.523599 0 0</pose>
          <velocity>0 0 0 0 -0 0</velocity>
          <acceleration>0 0 0 0 -0 0</acceleration>
          <wrench>0 0 0 0 -0 0</wrench>
        </link>
        <link name='left_railing_upright0'>
          <pose frame=''>2.59448 0.361602 0.15875 1.0472 -0 0</pose>
          <velocity>0 0 0 0 -0 0</velocity>
          <acceleration>0 0 0 0 -0 0</acceleration>
          <wrench>0 0 0 0 -0 0</wrench>
        </link>
        <link name='left_railing_upright1'>
          <pose frame=''>2.59448 0.823482 0.95875 1.0472 -0 0</pose>
          <velocity>0 0 0 0 -0 0</velocity>
          <acceleration>0 0 0 0 -0 0</acceleration>
          <wrench>0 0 0 0 -0 0</wrench>
        </link>
        <link name='left_railing_upright2'>
          <pose frame=''>2.59448 1.28536 1.75875 1.0472 -0 0</pose>
          <velocity>0 0 0 0 -0 0</velocity>
          <acceleration>0 0 0 0 -0 0</acceleration>
          <wrench>0 0 0 0 -0 0</wrench>
        </link>
        <link name='left_railing_upright3'>
          <pose frame=''>2.59448 1.74724 2.55875 1.0472 -0 0</pose>
          <velocity>0 0 0 0 -0 0</velocity>
          <acceleration>0 0 0 0 -0 0</acceleration>
          <wrench>0 0 0 0 -0 0</wrench>
        </link>
        <link name='left_side_wall'>
          <pose frame=''>2.59448 1.32939 1.2 1.0472 -0 0</pose>
          <velocity>0 0 0 0 -0 0</velocity>
          <acceleration>0 0 0 0 -0 0</acceleration>
          <wrench>0 0 0 0 -0 0</wrench>
        </link>
        <link name='right_side_wall'>
          <pose frame=''>3.49448 1.32939 1.2 1.0472 -0 0</pose>
          <velocity>0 0 0 0 -0 0</velocity>
          <acceleration>0 0 0 0 -0 0</acceleration>
          <wrench>0 0 0 0 -0 0</wrench>
        </link>
        <link name='step0'>
          <pose frame=''>3.04448 0.790525 0.266667 0 -0 0</pose>
          <velocity>0 0 0 0 -0 0</velocity>
          <acceleration>0 0 0 0 -0 0</acceleration>
          <wrench>0 0 0 0 -0 0</wrench>
        </link>
        <link name='step1'>
          <pose frame=''>3.04448 0.944485 0.533333 0 -0 0</pose>
          <velocity>0 0 0 0 -0 0</velocity>
          <acceleration>0 0 0 0 -0 0</acceleration>
          <wrench>0 0 0 0 -0 0</wrench>
        </link>
        <link name='step2'>
          <pose frame=''>3.04448 1.09844 0.8 0 -0 0</pose>
          <velocity>0 0 0 0 -0 0</velocity>
          <acceleration>0 0 0 0 -0 0</acceleration>
          <wrench>0 0 0 0 -0 0</wrench>
        </link>
        <link name='step3'>
          <pose frame=''>3.04448 1.2524 1.06667 0 -0 0</pose>
          <velocity>0 0 0 0 -0 0</velocity>
          <acceleration>0 0 0 0 -0 0</acceleration>
          <wrench>0 0 0 0 -0 0</wrench>
        </link>
        <link name='step4'>
          <pose frame=''>3.04448 1.40637 1.33333 0 -0 0</pose>
          <velocity>0 0 0 0 -0 0</velocity>
          <acceleration>0 0 0 0 -0 0</acceleration>
          <wrench>0 0 0 0 -0 0</wrench>
        </link>
        <link name='step5'>
          <pose frame=''>3.04448 1.56032 1.6 0 -0 0</pose>
          <velocity>0 0 0 0 -0 0</velocity>
          <acceleration>0 0 0 0 -0 0</acceleration>
          <wrench>0 0 0 0 -0 0</wrench>
        </link>
        <link name='step6'>
          <pose frame=''>3.04448 1.71429 1.86667 0 -0 0</pose>
          <velocity>0 0 0 0 -0 0</velocity>
          <acceleration>0 0 0 0 -0 0</acceleration>
          <wrench>0 0 0 0 -0 0</wrench>
        </link>
        <link name='step7'>
          <pose frame=''>3.04448 1.86824 2.13333 0 -0 0</pose>
          <velocity>0 0 0 0 -0 0</velocity>
          <acceleration>0 0 0 0 -0 0</acceleration>
          <wrench>0 0 0 0 -0 0</wrench>
        </link>
      </model>
      <model name='nist_stairs_120'>
        <pose frame=''>-2.54645 0.386562 0 0 -0 0</pose>
        <scale>1 1 1</scale>
        <link name='nist_stairs_120_link'>
          <pose frame=''>-2.54645 0.386562 0 0 -0 0</pose>
          <velocity>0 0 0 0 -0 0</velocity>
          <acceleration>0 0 0 0 -0 0</acceleration>
          <wrench>0 0 0 0 -0 0</wrench>
        </link>
      </model>
      <model name='quadruped'>
        <pose frame=''>-0.000648 0.000542 0.061356 0.001831 -0.000252 -0.001066</pose>
        <scale>1 1 1</scale>
        <link name='back_left_d'>
          <pose frame=''>-0.51058 0.056722 0.06133 -0.001832 0.000249 3.13893</pose>
          <velocity>-0.000194 -0.000179 -0.007391 0.002878 -0.003444 -3e-06</velocity>
          <acceleration>-0.012009 0.002446 -9.74522 -0.006839 -0.088395 5.1e-05</acceleration>
          <wrench>-0.012009 0.002446 -9.74522 0 -0 0</wrench>
        </link>
        <link name='back_left_u'>
          <pose frame=''>-0.110595 0.050659 0.06142 -0.001832 0.000249 3.13893</pose>
          <velocity>-0.000186 -0.000182 -0.00594 0.002884 -0.003444 -2e-06</velocity>
          <acceleration>0.027981 -0.002749 -9.27528 -0.006473 0.042347 0.001755</acceleration>
          <wrench>0.027981 -0.002749 -9.27528 0 -0 0</wrench>
        </link>
        <link name='back_right_d'>
          <pose frame=''>-0.510713 -0.053278 0.061128 -0.001832 0.000249 3.13893</pose>
          <velocity>-0.000194 -0.000179 -0.007731 0.002873 -0.003444 -3e-06</velocity>
          <acceleration>-0.01616 0.002477 -9.94945 -0.017766 -0.127112 0.000265</acceleration>
          <wrench>-0.01616 0.002477 -9.94945 0 -0 0</wrench>
        </link>
        <link name='back_right_u'>
          <pose frame=''>-0.110701 -0.049341 0.061237 -0.001832 0.000249 3.13893</pose>
          <velocity>-0.000195 -0.00018 -0.006349 0.002873 -0.003444 -3e-06</velocity>
          <acceleration>-0.018231 0.002928 -9.93007 -0.020789 -0.145696 0.000296</acceleration>
          <wrench>-0.018231 0.002928 -9.93007 0 -0 0</wrench>
        </link>
        <link name='dummy'>
          <pose frame=''>-0.000648 0.000542 0.061356 0.001831 -0.000252 -0.001066</pose>
          <velocity>-0.000192 -0.000181 -0.005745 0.00288 -0.003444 -3e-06</velocity>
          <acceleration>-0.002643 0.001285 -9.48228 -0.007473 -0.025796 0.000627</acceleration>
          <wrench>-0.002643 0.001285 -9.48228 0 -0 0</wrench>
        </link>
        <link name='front_left_d'>
          <pose frame=''>0.50941 0.054998 0.061586 0.001831 -0.000252 -0.001066</pose>
          <velocity>-0.000194 -0.000183 -0.003901 0.002877 -0.003444 -3e-06</velocity>
          <acceleration>-0.007407 0.001783 -9.85555 -0.007988 -0.023009 0.001348</acceleration>
          <wrench>-0.007407 0.001783 -9.85555 0 -0 0</wrench>
        </link>
        <link name='front_left_u'>
          <pose frame=''>0.109405 0.050424 0.061476 0.001831 -0.000252 -0.001066</pose>
          <velocity>-0.000194 -0.000182 -0.005289 0.002876 -0.003444 -3e-06</velocity>
          <acceleration>-0.009267 0.001634 -9.85112 -0.010768 -0.039047 0.001405</acceleration>
          <wrench>-0.009267 0.001634 -9.85112 0 -0 0</wrench>
        </link>
        <link name='front_right_d'>
          <pose frame=''>0.509293 -0.055002 0.061385 0.001831 -0.000252 -0.001066</pose>
          <velocity>-0.000191 -0.000184 -0.004246 0.002879 -0.003444 -3e-06</velocity>
          <acceleration>0.003911 -0.00131 -10.0848 0.002537 0.084071 -0.000292</acceleration>
          <wrench>0.003911 -0.00131 -10.0848 0 -0 0</wrench>
        </link>
        <link name='front_right_u'>
          <pose frame=''>0.109299 -0.049575 0.061293 0.001831 -0.000252 -0.001066</pose>
          <velocity>-0.000184 -0.000184 -0.005605 0.002882 -0.003444 -4e-06</velocity>
          <acceleration>0.033823 -0.008495 -10.0263 0.010072 0.123499 -0.002684</acceleration>
          <wrench>0.033823 -0.008495 -10.0263 0 -0 0</wrench>
        </link>
      </model>
      <light name='sun'>
        <pose frame=''>0 0 10 0 -0 0</pose>
      </light>
    </state>
    <gui fullscreen='0'>
      <camera name='user_camera'>
        <pose frame=''>5.5875 -6.73502 4.94415 0 0.379643 2.17619</pose>
        <view_controller>orbit</view_controller>
        <projection_type>perspective</projection_type>
      </camera>
    </gui>
  </world>
</sdf>
